function asyncGeneratorStep(gen, resolve, reject, _next, _throw, key, arg) { try { var info = gen[key](arg); var value = info.value; } catch (error) { reject(error); return; } if (info.done) { resolve(value); } else { Promise.resolve(value).then(_next, _throw); } }

function _asyncToGenerator(fn) { return function () { var self = this, args = arguments; return new Promise(function (resolve, reject) { var gen = fn.apply(self, args); function _next(value) { asyncGeneratorStep(gen, resolve, reject, _next, _throw, "next", value); } function _throw(err) { asyncGeneratorStep(gen, resolve, reject, _next, _throw, "throw", err); } _next(undefined); }); }; }

// Copyright 2016 Microsoft, Inc. All rights reserved.
// This code is governed by the BSD license found in the LICENSE file.

/*---
author: Brian Terlson <brian.terlson@microsoft.com>
esid: pending
description: >
  If a default expression throws, the promise is rejected.
info: |
  This is different from generators which will throw the error out of the generator
  when it is called.
flags: [async]
---*/
var y = null;

function foo() {
  return _foo.apply(this, arguments);
}

function _foo() {
  _foo = _asyncToGenerator( /*#__PURE__*/regeneratorRuntime.mark(function _callee() {
    var x,
        _args = arguments;
    return regeneratorRuntime.wrap(function _callee$(_context) {
      while (1) {
        switch (_context.prev = _context.next) {
          case 0:
            x = _args.length > 0 && _args[0] !== undefined ? _args[0] : y();

          case 1:
          case "end":
            return _context.stop();
        }
      }
    }, _callee);
  }));
  return _foo.apply(this, arguments);
}

foo().then(function () {
  $DONE('promise should be rejected');
}, function () {
  $DONE();
});